Workbook

Sheet Assignment_Data7 to 10
A1: Age | B1: Salary | C1: Purchase_Count | D1: Satisfaction_Score | E1: Visit_Frequency
A2: 56 | B2: 158767 | C2: 17 | D2: 1.9759586 | E2: 7
A3: 46 | B3: 149375 | C3: 38 | D3: 4.8920422 | E3: 5
A4: 32 | B4: 161330 | C4: 24 | D4: 2.5723909 | E4: 3
A5: 60 | B5: 64504 | C5: 5 | D5: 2.5723909 | E5: 12
A6: 25 | B6: 38986 | C6: 34 | D6: 3.5245545 | E6: 16
A7: 38 | B7: 86858 | C7: 6 | D7: 4.1792452 | E7: 19
A8: 56 | B8: 154312 | C8: 22 | D8: 3.0105484 | E8: 5
A9: 36 | B9: 37666 | C9: 11 | D9: 3.3076155 | E9: 14
A10: 40 | B10: 63660 | C10: 48 | D10: 2.9700708 | E10: 5
A11: 28 | B11: 159633 | C11: 16 | D11: 1.780972 | E11: 15
A12: 28 | B12: 51854 | C12: 33 | D12: 3.8898085 | E12: 17
A13: 41 | B13: 89505 | C13: 9 | D13: 2.1230895 | E13: 14
... A85: 35 | B85: 64353 | C85: 36 | D85: 4.1807448 | E85: 17
A86: 64 | B86: 77733 | C86: 33 | D86: 2.083329 | E86: 13 | HE86: 123506
A87: 41 | B87: 90318 | C87: 4 | D87: 2.7558857 | E87: 3 | HE87: 0
A88: 43 | B88: 179736 | C88: 33 | D88: 1.3138255 | E88: 9 | HE88: 123506
A89: 42 | B89: 92172 | C89: 14 | D89: 1.101403 | E89: 17 | HE89: #N/A
A90: 62 | B90: 118264 | C90: 21 | D90: 4.8505937 | E90: 17 | HE90: #DIV/0!
A91: 58 | B91: 51736 | C91: 48 | D91: 4.3439205 | E91: 16 | HE91: #DIV/0!
A92: 46 | B92: 137859 | C92: 20 | D92: 3.7838968 | E92: 13 | HE92: #DIV/0!
A93: 32 | B93: 137181 | C93: 8 | D93: 2.6358118 | E93: 19 | HE93: #DIV/0!
A94: 62 | B94: 156926 | C94: 7 | D94: 1.6931773 | E94: 17 | HE94: 0
A95: 18 | B95: 115084 | C95: 3 | D95: 1.6257482 | E95: 4 | HE95: 123506
A96: 42 | B96: 32392 | C96: 17 | D96: 2.0009716 | E96: 12 | HE96: 123506
A97: 24 | B97: 80680 | C97: 33 | D97: 3.1969067 | E97: 9 | HE97: 123506
A98: 26 | B98: 75859 | C98: 48 | D98: 3.8583837 | E98: 19 | HE98: 1
A99: 41 | B99: 150657 | C99: 12 | D99: 3.6407895 | E99: 12
A100: 18 | B100: 95467 | C100: 22 | D100: 2.1197356 | E100: 9
A101: 61 | B101: 123506 | C101: 22 | D101: 4.8194611 | E101: 7

Sheet Statistics
A2: Que 1 | B2: Calculate the mean, median, and mode of 'Age'.
A3: Solution
B4: Mean | C4: =AVERAGE('Assignment_Data7 to 10'!A2:A101) -> 40.88
B5: Median | C5: =MEDIAN('Assignment_Data7 to 10'!A2:A101) -> 41
B6: Mode | C6: =MODE('Assignment_Data7 to 10'!A2:A101) -> 61
A8: Que 2 | B8: Find the standard deviation and variance of 'Salary'.
B10: Standard Deviation | C10: =_xlfn.STDEV.S('Assignment_Data7 to 10'!B2:B101) -> 44418.086
B11: Variance | C11: =_xlfn.VAR.S('Assignment_Data7 to 10'!B2:B101) -> 1.9729664e+09
A14: Que 3 | B14: Compute the skewness and kurtosis of 'Purchase_Count'.
B16: Skewness | C16: =SKEW('Assignment_Data7 to 10'!C2:C101) -> 0.048663602
B17: Kurtosis | C17: =KURT('Assignment_Data7 to 10'!C2:C101) -> -1.0551591
A20: Que 4 | B20: What is the correlation between 'Salary' and 'Satisfaction_Score'?
B22: Corellation | C22: =CORREL('Assignment_Data7 to 10'!B2:B101,'Assignment_Data7 to 10'!D2:D101) -> -0.14789962
A25: Que 5 | B25: Get the summary statistics (count, mean, std, min, 25%, 50%, 75%, max) for every column.
B27: Age | C27: Salary | D27: Purchase_Count | E27: Satisfaction_Score | F27: Visit_Frequency
A28: Count | B28: =COUNT('Assignment_Data7 to 10'!A2:A101) -> 100 | C28: =COUNT('Assignment_Data7 to 10'!B2:B101) -> 100 | D28: =COUNT('Assignment_Data7 to 10'!C2:C101) -> 100 | E28: =COUNT('Assignment_Data7 to 10'!D2:D101) -> 100 | F28: =COUNT('Assignment_Data7 to 10'!E2:E101) -> 100
A29: Mean | B29: =AVERAGE('Assignment_Data7 to 10'!A2:A101) -> 40.88 | C29: =AVERAGE('Assignment_Data7 to 10'!B2:B101) -> 109321.51 | D29: =AVERAGE('Assignment_Data7 to 10'!C2:C101) -> 24.47 | E29: =AVERAGE('Assignment_Data7 to 10'!D2:D101) -> 3.1156903 | F29: =AVERAGE('Assignment_Data7 to 10'!E2:E101) -> 9.96
A30: Std | B30: =_xlfn.STDEV.S('Assignment_Data7 to 10'!A2:A101) -> 13.99082 | C30: =_xlfn.STDEV.S('Assignment_Data7 to 10'!B2:B101) -> 44418.086 | D30: =_xlfn.STDEV.S('Assignment_Data7 to 10'!C2:C101) -> 13.994555 | E30: =_xlfn.STDEV.S('Assignment_Data7 to 10'!D2:D101) -> 1.1636024 | F30: =_xlfn.STDEV.S('Assignment_Data7 to 10'!E2:E101) -> 5.8204099
A31: min | B31: =MIN('Assignment_Data7 to 10'!A2:A101) -> 18 | C31: =MIN('Assignment_Data7 to 10'!B2:B101) -> 27693 | D31: =MIN('Assignment_Data7 to 10'!C2:C101) -> 1 | E31: =MIN('Assignment_Data7 to 10'!D2:D101) -> 1.0618265 | F31: =MIN('Assignment_Data7 to 10'!E2:E101) -> 1
A32: 0.25 | B32: =_xlfn.QUARTILE.INC('Assignment_Data7 to 10'!A2:A101,1) -> 30.5 | C32: =_xlfn.QUARTILE.INC('Assignment_Data7 to 10'!B2:B101,1) -> 73576.75 | D32: =_xlfn.QUARTILE.INC('Assignment_Data7 to 10'!C2:C101,1) -> 13.5 | E32: =_xlfn.QUARTILE.INC('Assignment_Data7 to 10'!D2:D101,1) -> 2.1673168 | F32: =_xlfn.QUARTILE.INC('Assignment_Data7 to 10'!E2:E101,1) -> 4.75
A33: 0.5 | B33: =_xlfn.QUARTILE.INC('Assignment_Data7 to 10'!A2:A101,2) -> 41 | C33: =_xlfn.QUARTILE.INC('Assignment_Data7 to 10'!B2:B101,2) -> 118025.5 | D33: =_xlfn.QUARTILE.INC('Assignment_Data7 to 10'!C2:C101,2) -> 24 | E33: =_xlfn.QUARTILE.INC('Assignment_Data7 to 10'!D2:D101,2) -> 3.1665595 | F33: =_xlfn.QUARTILE.INC('Assignment_Data7 to 10'!E2:E101,2) -> 10
A34: 0.75 | B34: =_xlfn.QUARTILE.INC('Assignment_Data7 to 10'!A2:A101,3) -> 53.25 | C34: =_xlfn.QUARTILE.INC('Assignment_Data7 to 10'!B2:B101,3) -> 147727.75 | D34: =_xlfn.QUARTILE.INC('Assignment_Data7 to 10'!C2:C101,3) -> 35 | E34: =_xlfn.QUARTILE.INC('Assignment_Data7 to 10'!D2:D101,3) -> 4.1796201 | F34: =_xlfn.QUARTILE.INC('Assignment_Data7 to 10'!E2:E101,3) -> 16
A35: Max | B35: =_xlfn.QUARTILE.INC('Assignment_Data7 to 10'!A2:A101,4) -> 64 | C35: =_xlfn.QUARTILE.INC('Assignment_Data7 to 10'!B2:B101,4) -> 179736 | D35: =_xlfn.QUARTILE.INC('Assignment_Data7 to 10'!C2:C101,4) -> 49 | E35: =_xlfn.QUARTILE.INC('Assignment_Data7 to 10'!D2:D101,4) -> 4.9602154 | F35: =_xlfn.QUARTILE.INC('Assignment_Data7 to 10'!E2:E101,4) -> 19
A38: Que 6 | B38: Plot the histogram of 'Visit_Frequency' and comment on its skewness.
B55: Skeness | C55: Looks like right skewed- positively skewed
A58: Que 7 | B58: Identify if 'Satisfaction_Score' has any outliers using standard deviation method.
B60: Mean | C60: =AVERAGE('Assignment_Data7 to 10'!D2:D101) -> 3.1156903 | E60: Value | F60: Std > mean/3
B61: Std | C61: =_xlfn.STDEV.S('Assignment_Data7 to 10'!D2:D101) -> 1.1636024 | E61: =C60/3 -> 1.0385634 | F61: =C61>E61 -> TRUE
B63: if std <= 1/3rd of the mean - means data is quite consistent - if std>1/3rd of the mean - means data is dispersed chances of having the outlieres
A66: Que 8 | B66: Calculate the coefficient of variation for 'Salary'.
B68: std | C68: =_xlfn.STDEV.S('Assignment_Data7 to 10'!B2:B101) -> 44418.086
B69: mean | C69: =AVERAGE('Assignment_Data7 to 10'!B2:B101) -> 109321.51
B71: CV | C71: =C68/C69 -> 0.40630692
A74: Que 9 | B74: Find the interquartile range (IQR) for 'Purchase_Count'.
B76: IQR | C76: =_xlfn.QUARTILE.INC('Assignment_Data7 to 10'!C2:C101,4)-_xlfn.QUARTILE.INC('Assignment_Data7 to 10'!C2:C101,0) -> 48
A79: Que 10 | B79: Compute the Pearson correlation matrix for the entire dataset.
C81: Age | D81: Salary | E81: Purchase_Count | F81: Satisfaction_Score | G81: Visit_Frequency
B82: Age | C82: 1
B83: Salary | C83: -0.017658358 | D83: 1
B84: Purchase_Count | C84: 0.061269928 | D84: -0.0015562351 | E84: 1
...

Sheet Excel - Pivot
A1: Que1 | D1: Que 3 | G1: Que 2
A3: Age | B3: Average of Salary | D3: Visit Frequency | E3: Count of Visit_Frequency | G3: Satisfaction Score | H3: Sum of Purchase_Count
A4: 18 | B4: 105275.5 | D4: 1 | E4: 6 | G4: 1.0618265 | H4: 26
A5: 19 | B5: 118393.25 | D5: 2 | E5: 4 | G5: 1.0972639 | H5: 6
A6: 20 | B6: 51977 | D6: 3 | E6: 7 | G6: 1.101403 | H6: 14
A7: 21 | B7: 154100.67 | D7: 4 | E7: 8 | G7: 1.122001 | H7: 8
A8: 23 | B8: 150117 | D8: 5 | E8: 10 | G8: 1.1437691 | H8: 24
A9: 24 | B9: 120777.33 | D9: 7 | E9: 5 | G9: 1.1493928 | H9: 36
A10: 25 | B10: 103968 | D10: 8 | E10: 2 | G10: 1.2067269 | H10: 29
A11: 26 | B11: 109990.67 | D11: 9 | E11: 5 | G11: 1.3138255 | H11: 33
A12: 27 | B12: 46959 | D12: 10 | E12: 5 | G12: 1.3413899 | H12: 25
A13: 28 | B13: 105743.5 | D13: 11 | E13: 3 | G13: 1.3759278 | H13: 3
A14: 29 | B14: 133066 | D14: 12 | E14: 9 | G14: 1.388706 | H14: 25
A15: 31 | B15: 96532 | D15: 13 | E15: 5 | G15: 1.5082421 | H15: 20
... A21: 37 | B21: 68585 | D21: 19 | E21: 7 | G21: 1.780972 | H21: 16
A22: 38 | B22: 87180.5 | D22: Grand Total | E22: 100 | G22: 1.8632841 | H22: 25
A23: 39 | B23: 138410.5 | G23: 1.9759586 | H23: 17
A24: 40 | B24: 91108.5 | G24: 2.0009716 | H24: 17
A25: 41 | B25: 95601.4 | G25: 2.083329 | H25: 33
A26: 42 | B26: 83998.25 | G26: 2.1197356 | H26: 22
A27: 43 | B27: 158509.67 | G27: 2.1230895 | H27: 9
A28: 44 | B28: 162982 | G28: 2.146165 | H28: 11
A29: 45 | B29: 125103.5 | G29: 2.1743674 | H29: 49
A30: 46 | B30: 150027.33 | G30: 2.1777956 | H30: 41
A31: 47 | B31: 60222 | G31: 2.267688 | H31: 39
A32: 48 | B32: 28748 | G32: 2.2918259 | H32: 41
A33: 50 | B33: 49538 | G33: 2.3519806 | H33: 48
A34: 51 | B34: 165546 | G34: 2.4379646 | H34: 48
... A46: 64 | B46: 93498.5 | G46: 3.0105484 | H46: 22
A47: Grand Total | B47: 109321.51 | G47: 3.0453696 | H47: 5
G48: 3.0652014 | H48: 16
A49: Que 4 | G49: 3.0733186 | H49: 42
G50: 3.088973 | H50: 35
A51: Age Range | B51: Min of Salary | C51: Max of Salary | D51: Average of Salary | G51: 3.1254185 | H51: 18
A52: 18-26 | B52: 38986 | C52: 178371 | D52: 114509.76 | G52: 3.1625405 | H52: 46
A53: 27-35 | B53: 38545 | C53: 174213 | D53: 108689.28 | G53: 3.1705785 | H53: 24
A54: 36-44 | B54: 32392 | C54: 179736 | D54: 102892.26 | G54: 3.1969067 | H54: 33
A55: 45-53 | B55: 28748 | C55: 177906 | D55: 121085 | G55: 3.227205 | H55: 40
A56: 54-62 | B56: 27693 | C56: 171779 | D56: 107448.48 | G56: 3.2802447 | H56: 28
A57: 63-71 | B57: 50939 | C57: 156278 | D57: 93498.5 | G57: 3.3076155 | H57: 11
...
